accessing
unexpectedError: anObject
	unexpectedError := anObject